<robot name="myfirstarm">

	<material name="black">
		<color rgba="0 0 0 1"/>
	</material>
	<material name="purple">
		<color rgba="0.8 0 0.6 1"/>
	</material>
	<material name="white">
		<color rgba="1 1 1 1"/>
	</material>

	<link name="base_link">
		<visual>
			<geometry>
				<cylinder length="0.25" radius="0.25"/>
			</geometry>
			<material name="black"/>
		</visual>
	</link>

	<link name="link_1">
		<visual>
			<geometry>
				<cylinder length="1" radius="0.075"/>
			</geometry>
			<material name="purple"/>
			<origin xyz="0 0 0.5" rpy="0 0 0"/>
		</visual>
	</link>

	<joint name="joint_1" type="continuous">
		<parent link="base_link"/>
		<child link="link_1"/>
		<origin xyz="0 0 0.125" rpy="0 0 0"/>
		<axis xyz="0 0 1"/>
	</joint>

	<link name="link_2">
		<visual>
			<geometry>
				<sphere radius="0.15"/>
			</geometry>
			<material name="black"/>
		</visual>
	</link>

	<joint name="joint_2" type="fixed">
		<parent link="link_1"/>
		<child link="link_2"/>
		<origin xyz="0 0 1.15" rpy="0 0 0"/>
	</joint>

	<link name="link_3">
		<visual>
			<geometry>
				<sphere radius="0.15"/>
			</geometry>
			<material name="black"/>
		</visual>
	</link>

	<joint name="joint_3" type="revolute">
		<parent link="link_2"/>
		<child link="link_3"/>
		<origin xyz="0 0 0" rpy="0 0 0"/>
		<axis xyz="1 0 0"/>
		<limit effort="1000" lower="-0.5235" upper="1.047" velocity="0.75"/>
	</joint>

	<link name="link_4">
		<visual>
			<geometry>
				<cylinder length="1" radius="0.075"/>
			</geometry>
			<material name="purple"/>
		</visual>
	</link>

	<joint name="joint_4" type="fixed">
		<parent link="link_3"/>
		<child link="link_4"/>
		<origin xyz="0 0.65 0" rpy="1.5707 0 0"/>
	</joint>

	<link name="link_5">
		<visual>
			<geometry>
				<sphere radius="0.15"/>
			</geometry>
			<material name="black"/>
		</visual>
	</link>

	<joint name="joint_5" type="fixed">
		<parent link="link_4"/>
		<child link="link_5"/>
		<origin xyz="0 0 -0.65" rpy="0 0 0"/>
	</joint>

	<link name="link_6">
		<visual>
			<geometry>
				<sphere radius="0.15"/>
			</geometry>
			<material name="black"/>
		</visual>
	</link>

	<joint name="joint_6" type="revolute">
		<parent link="link_5"/>
		<child link="link_6"/>
		<origin xyz="0 0 0" rpy="0 0 0"/>
		<axis xyz="1 0 0"/>
		<limit effort="1000" lower="0" upper="1.5707" velocity="0.75"/>
	</joint>

	<link name="link_7">
		<visual>
			<geometry>
				<cylinder length="0.65" radius="0.075"/>
			</geometry>
			<material name="purple"/>
		</visual>
	</link>

	<joint name="joint_7" type="fixed">
		<parent link="link_6"/>
		<child link="link_7"/>
		<origin xyz="0 -0.475 0" rpy="1.5707 0 0"/>
	</joint>

	<link name="link_8">
		<visual>
			<geometry>
				<sphere radius="0.15"/>
			</geometry>
			<material name="black"/>
		</visual>
	</link>

	<joint name="joint_8" type="fixed">
		<parent link="link_7"/>
		<child link="link_8"/>
		<origin xyz="0 0 0.475" rpy="0 0 0"/>
	</joint>

	<link name="link_9">
		<visual>
			<geometry>
				<sphere radius="0.15"/>
			</geometry>
			<material name="black"/>
		</visual>
	</link>

	<joint name="joint_9" type="revolute">
		<parent link="link_8"/>
		<child link="link_9"/>
		<origin xyz="0 0 0" rpy="0 0 0"/>
		<axis xyz="1 0 0"/>
		<limit effort="1000" lower="-0.7853" upper="0.5235" velocity="0.75"/>
	</joint>

	<link name="link_10">
		<visual>
			<geometry>
				<cylinder length="0.25" radius="0.075"/>
			</geometry>
			<material name="purple"/>
		</visual>
	</link>

	<joint name="joint_10" type="fixed">
		<parent link="link_9"/>
		<child link="link_10"/>
		<origin xyz="0 -0.275 0" rpy="1.5707 0 0"/>
	</joint>

	<link name="link_11">
		<visual>
			<geometry>
				<sphere radius="0.075"/>
			</geometry>
			<material name="black"/>
		</visual>
	</link>

	<joint name="joint_11" type="continuous">
		<parent link="link_10"/>
		<child link="link_11"/>
		<origin xyz="0 0 0.2" rpy="0 0 0"/>
		<axis xyz="0 0 1"/>
	</joint>

	<link name="link_12">
		<visual>
			<geometry>
				<sphere radius="0.075"/>
			</geometry>
			<material name="black"/>
		</visual>
	</link>

	<joint name="joint_12" type="revolute">
		<parent link="link_11"/>
		<child link="link_12"/>
		<origin xyz="0 0 0" rpy="0 0 0"/>	
		<axis xyz="0 1 0"/>
		<limit effort="1000" lower="0" upper="0.67" velocity="0.75"/>
	</joint>

	<link name="link_13">
		<visual>
			<geometry>
				<cylinder length="0.05" radius="0.025"/>
			</geometry>
			<material name="white"/>
		</visual>
	</link>

	<joint name="joint_13" type="fixed">
		<parent link="link_12"/>
		<child link="link_13"/>
		<origin xyz="-0.1 0 0" rpy="0 1.5707 0"/>
	</joint>

	<link name="link_14">
		<visual>
			<geometry>
				<sphere radius="0.03"/>
			</geometry>
			<material name="white"/>
		</visual>
	</link>

	<joint name="joint_14" type="fixed">
		<parent link="link_13"/>
		<child link="link_14"/>
		<origin xyz="0 0 -0.055" rpy="0 0 0"/>
	</joint>

	<link name="link_15">
		<visual>
			<geometry>
				<cylinder length="0.125" radius="0.025"/>
			</geometry>
			<material name="white"/>
		</visual>
	</link>

	<joint name="joint_15" type="fixed">
		<parent link="link_14"/>
		<child link="link_15"/>
		<origin xyz="-0.0925 0 0" rpy="0 1.5707 0"/>
	</joint>

	<link name="link_16">
		<visual>
			<geometry>
				<sphere radius="0.025"/>
			</geometry>
			<material name="white"/>
		</visual>
	</link>

	<joint name="joint_16" type="fixed">
		<parent link="link_15"/>
		<child link="link_16"/>
		<origin xyz="0 0 -0.0625" rpy="0 0 0"/>
	</joint>

	<link name="link_17">
		<visual>
			<geometry>
				<sphere radius="0.075"/>
			</geometry>
			<material name="black"/>
		</visual>
	</link>

	<joint name="joint_17" type="revolute">
		<parent link="link_11"/>
		<child link="link_17"/>
		<origin xyz="0 0 0" rpy="0 0 0"/>
		<axis xyz="0 -1 0"/>
		<limit effort="1000" lower="0" upper="0.67" velocity="0.75"/>
	</joint>

	<link name="link_18">
		<visual>
			<geometry>
				<cylinder length="0.05" radius="0.025"/>
			</geometry>
			<material name="white"/>
		</visual>
	</link>

	<joint name="joint_18" type="fixed">
		<parent link="link_17"/>
		<child link="link_18"/>
		<origin xyz="0.1 0 0" rpy="0 1.5707 0"/>
	</joint>

	<link name="link_19">
		<visual>
			<geometry>
				<sphere radius="0.03"/>
			</geometry>
			<material name="white"/>
		</visual>
	</link>

	<joint name="joint_19" type="fixed">
		<parent link="link_18"/>
		<child link="link_19"/>
		<origin xyz="0 0 0.055" rpy="0 0 0"/>
	</joint>

	<link name="link_20">
		<visual>
			<geometry>
				<cylinder length="0.125" radius="0.025"/>
			</geometry>
			<material name="white"/>
		</visual>
	</link>

	<joint name="joint_20" type="fixed">
		<parent link="link_19"/>
		<child link="link_20"/>
		<origin xyz="-0.0925 0 0" rpy="0 1.5707 0"/>
	</joint>

	<link name="link_21">
		<visual>
			<geometry>
				<sphere radius="0.025"/>
			</geometry>
			<material name="white"/>
		</visual>
	</link>

	<joint name="joint_21" type="fixed">
		<parent link="link_20"/>
		<child link="link_21"/>
		<origin xyz="0 0 -0.0625" rpy="0 0 0"/>
	</joint>

</robot>
